DEBUG:root:<ul class="errorlist"><li>cpf<ul class="errorlist"><li>Invalid CPF number.</li></ul></li></ul>
DEBUG:root:
ERROR:django.request:Internal Server Error: /cliente/ajax
Traceback (most recent call last):
  File "C:\Users\igoro\AppData\Local\Programs\Python\Python310\lib\site-packages\django\core\handlers\exception.py", line 47, in inner
    response = get_response(request)
  File "C:\Users\igoro\AppData\Local\Programs\Python\Python310\lib\site-packages\django\core\handlers\base.py", line 181, in _get_response
    response = wrapped_callback(request, *callback_args, **callback_kwargs)
  File "C:\Users\igoro\OneDrive\Documentos\GitHub\TCC\app\views.py", line 108, in clientePreview
    resultado = predict(values)
  File "C:\Users\igoro\OneDrive\Documentos\GitHub\TCC\app\data.py", line 84, in predict
    res[0] = clf[1].predict(values)[0]
AttributeError: 'int' object has no attribute 'predict'
ERROR:django.request:Internal Server Error: /cliente/ajax
Traceback (most recent call last):
  File "C:\Users\igoro\AppData\Local\Programs\Python\Python310\lib\site-packages\django\core\handlers\exception.py", line 47, in inner
    response = get_response(request)
  File "C:\Users\igoro\AppData\Local\Programs\Python\Python310\lib\site-packages\django\core\handlers\base.py", line 181, in _get_response
    response = wrapped_callback(request, *callback_args, **callback_kwargs)
  File "C:\Users\igoro\OneDrive\Documentos\GitHub\TCC\app\views.py", line 108, in clientePreview
    resultado = predict(values)
  File "C:\Users\igoro\OneDrive\Documentos\GitHub\TCC\app\data.py", line 84, in predict
    res[0] = clf[1].predict(values)[0]
AttributeError: 'int' object has no attribute 'predict'
DEBUG:root:
INFO:django.utils.autoreload:C:\Users\igoro\OneDrive\Documentos\GitHub\TCC\app\views.py changed, reloading.
